Traceback (most recent call last):
  File "c:/Users/ailab6/Documents/GitHub/CityLearn - 복사본/dqn.py", line 123, in <module>
    main()
  File "c:/Users/ailab6/Documents/GitHub/CityLearn - 복사본/dqn.py", line 120, in main
    agent.train(max_episodes=1000)
  File "c:/Users/ailab6/Documents/GitHub/CityLearn - 복사본/dqn.py", line 105, in train
    action = self.model.get_action(state)
  File "c:/Users/ailab6/Documents/GitHub/CityLearn - 복사본/dqn.py", line 67, in get_action
    q_value = self.predict(state)[0]
  File "c:/Users/ailab6/Documents/GitHub/CityLearn - 복사본/dqn.py", line 61, in predict
    return self.model.predict(state)
  File "C:\Users\ailab6\.conda\envs\citylearn\lib\site-packages\tensorflow_core\python\keras\engine\training.py", line 909, in predict
    use_multiprocessing=use_multiprocessing)
  File "C:\Users\ailab6\.conda\envs\citylearn\lib\site-packages\tensorflow_core\python\keras\engine\training_v2.py", line 462, in predict
    steps=steps, callbacks=callbacks, **kwargs)
  File "C:\Users\ailab6\.conda\envs\citylearn\lib\site-packages\tensorflow_core\python\keras\engine\training_v2.py", line 444, in _model_iteration
    total_epochs=1)
  File "C:\Users\ailab6\.conda\envs\citylearn\lib\site-packages\tensorflow_core\python\keras\engine\training_v2.py", line 123, in run_one_epoch
    batch_outs = execution_function(iterator)
  File "C:\Users\ailab6\.conda\envs\citylearn\lib\site-packages\tensorflow_core\python\keras\engine\training_v2_utils.py", line 86, in execution_function
    distributed_function(input_fn))
  File "C:\Users\ailab6\.conda\envs\citylearn\lib\site-packages\tensorflow_core\python\eager\def_function.py", line 457, in __call__
    result = self._call(*args, **kwds)
  File "C:\Users\ailab6\.conda\envs\citylearn\lib\site-packages\tensorflow_core\python\eager\def_function.py", line 526, in _call
    return self._concrete_stateful_fn._filtered_call(canon_args, canon_kwds)  # pylint: disable=protected-access
  File "C:\Users\ailab6\.conda\envs\citylearn\lib\site-packages\tensorflow_core\python\eager\function.py", line 1141, in _filtered_call
    self.captured_inputs)
  File "C:\Users\ailab6\.conda\envs\citylearn\lib\site-packages\tensorflow_core\python\eager\function.py", line 1224, in _call_flat
    ctx, args, cancellation_manager=cancellation_manager)
  File "C:\Users\ailab6\.conda\envs\citylearn\lib\site-packages\tensorflow_core\python\eager\function.py", line 511, in call
    ctx=ctx)
  File "C:\Users\ailab6\.conda\envs\citylearn\lib\site-packages\tensorflow_core\python\eager\execute.py", line 67, in quick_execute
    six.raise_from(core._status_to_exception(e.code, message), None)
  File "<string>", line 3, in raise_from
tensorflow.python.framework.errors_impl.InternalError:  Blas GEMM launch failed : a.shape=(1, 4), b.shape=(4, 32), m=1, n=32, k=4
	 [[node sequential/dense/MatMul (defined at C:\Users\ailab6\.conda\envs\citylearn\lib\site-packages\tensorflow_core\python\framework\ops.py:1751) ]] [Op:__inference_distributed_function_332]

Function call stack:
distributed_function

